2022-08-09 20:58:05,955 INFO    MainThread:10093 [internal.py:wandb_internal():90] W&B internal server running at pid: 10093, started at: 2022-08-09 20:58:05.954713
2022-08-09 20:58:05,957 INFO    WriterThread:10093 [datastore.py:open_for_write():75] open: /home/mgatlin3/FT/wandb/run-20220809_205805-8qyd8eum/run-8qyd8eum.wandb
2022-08-09 20:58:05,961 DEBUG   SenderThread:10093 [sender.py:send():232] send: header
2022-08-09 20:58:05,961 DEBUG   SenderThread:10093 [sender.py:send():232] send: run
2022-08-09 20:58:06,036 ERROR   SenderThread:10093 [internal_api.py:execute():143] 403 response executing GraphQL.
2022-08-09 20:58:06,037 ERROR   SenderThread:10093 [internal_api.py:execute():144] {"errors":[{"message":"permission denied","path":["upsertBucket"],"extensions":{"code":"PERMISSION_ERROR"}}],"data":{"upsertBucket":null}}
2022-08-09 20:58:06,960 INFO    WriterThread:10093 [datastore.py:close():279] close: /home/mgatlin3/FT/wandb/run-20220809_205805-8qyd8eum/run-8qyd8eum.wandb
2022-08-09 20:58:06,960 INFO    HandlerThread:10093 [handler.py:finish():806] shutting down handler
2022-08-09 20:58:06,960 ERROR   MainThread:10093 [internal.py:wandb_internal():165] Thread SenderThread:
Traceback (most recent call last):
  File "/home/mgatlin3/.local/lib/python3.9/site-packages/wandb/sdk/lib/retry.py", line 102, in __call__
    result = self._call_fn(*args, **kwargs)
  File "/home/mgatlin3/.local/lib/python3.9/site-packages/wandb/sdk/internal/internal_api.py", line 140, in execute
    return self.client.execute(*args, **kwargs)
  File "/home/mgatlin3/.local/lib/python3.9/site-packages/wandb/vendor/gql-0.2.0/wandb_gql/client.py", line 52, in execute
    result = self._get_result(document, *args, **kwargs)
  File "/home/mgatlin3/.local/lib/python3.9/site-packages/wandb/vendor/gql-0.2.0/wandb_gql/client.py", line 60, in _get_result
    return self.transport.execute(document, *args, **kwargs)
  File "/home/mgatlin3/.local/lib/python3.9/site-packages/wandb/vendor/gql-0.2.0/wandb_gql/transport/requests.py", line 39, in execute
    request.raise_for_status()
  File "/home/mgatlin3/.conda/envs/poop/lib/python3.9/site-packages/requests/models.py", line 1021, in raise_for_status
    raise HTTPError(http_error_msg, response=self)
requests.exceptions.HTTPError: 403 Client Error: Forbidden for url: https://api.wandb.ai/graphql

During handling of the above exception, another exception occurred:

Traceback (most recent call last):
  File "/home/mgatlin3/.local/lib/python3.9/site-packages/wandb/apis/normalize.py", line 22, in wrapper
    return func(*args, **kwargs)
  File "/home/mgatlin3/.local/lib/python3.9/site-packages/wandb/sdk/internal/internal_api.py", line 1318, in upsert_run
    response = self.gql(mutation, variable_values=variable_values, **kwargs)
  File "/home/mgatlin3/.local/lib/python3.9/site-packages/wandb/sdk/lib/retry.py", line 118, in __call__
    if not check_retry_fn(e):
  File "/home/mgatlin3/.local/lib/python3.9/site-packages/wandb/util.py", line 879, in no_retry_auth
    raise CommError("Permission denied, ask the project owner to grant you access")
wandb.errors.CommError: Permission denied, ask the project owner to grant you access

During handling of the above exception, another exception occurred:

Traceback (most recent call last):
  File "/home/mgatlin3/.local/lib/python3.9/site-packages/wandb/sdk/internal/internal_util.py", line 51, in run
    self._run()
  File "/home/mgatlin3/.local/lib/python3.9/site-packages/wandb/sdk/internal/internal_util.py", line 102, in _run
    self._process(record)
  File "/home/mgatlin3/.local/lib/python3.9/site-packages/wandb/sdk/internal/internal.py", line 310, in _process
    self._sm.send(record)
  File "/home/mgatlin3/.local/lib/python3.9/site-packages/wandb/sdk/internal/sender.py", line 234, in send
    send_handler(record)
  File "/home/mgatlin3/.local/lib/python3.9/site-packages/wandb/sdk/internal/sender.py", line 692, in send_run
    self._init_run(run, config_value_dict)
  File "/home/mgatlin3/.local/lib/python3.9/site-packages/wandb/sdk/internal/sender.py", line 716, in _init_run
    server_run, inserted = self._api.upsert_run(
  File "/home/mgatlin3/.local/lib/python3.9/site-packages/wandb/apis/normalize.py", line 58, in wrapper
    raise CommError(message, err).with_traceback(sys.exc_info()[2])
  File "/home/mgatlin3/.local/lib/python3.9/site-packages/wandb/apis/normalize.py", line 22, in wrapper
    return func(*args, **kwargs)
  File "/home/mgatlin3/.local/lib/python3.9/site-packages/wandb/sdk/internal/internal_api.py", line 1318, in upsert_run
    response = self.gql(mutation, variable_values=variable_values, **kwargs)
  File "/home/mgatlin3/.local/lib/python3.9/site-packages/wandb/sdk/lib/retry.py", line 118, in __call__
    if not check_retry_fn(e):
  File "/home/mgatlin3/.local/lib/python3.9/site-packages/wandb/util.py", line 879, in no_retry_auth
    raise CommError("Permission denied, ask the project owner to grant you access")
wandb.errors.CommError: Permission denied, ask the project owner to grant you access
2022-08-09 20:58:08,979 INFO    MainThread:10093 [internal.py:handle_exit():80] Internal process exited
