Traceback (most recent call last):
  File "c:\Users\apopa6\Desktop\feces_thesis\CNN-LSTM.py", line 29, in <module>
    train_generator = datagen.flow_from_directory(
  File "C:\Users\apopa6\Anaconda3\envs\first_ml\lib\site-packages\keras\preprocessing\image.py", line 1469, in flow_from_directory
    return DirectoryIterator(
  File "C:\Users\apopa6\Anaconda3\envs\first_ml\lib\site-packages\keras\preprocessing\image.py", line 491, in __init__
    super().set_processing_attrs(image_data_generator, target_size, color_mode,
  File "C:\Users\apopa6\Anaconda3\envs\first_ml\lib\site-packages\keras\preprocessing\image.py", line 287, in set_processing_attrs
    raise ValueError('Invalid color mode:', color_mode,
ValueError: ('Invalid color mode:', 'greyscale', '; expected "rgb", "rgba", or "grayscale".')