Found 0 images belonging to 4 classes.
Found 0 images belonging to 4 classes.
Found 0 images belonging to 4 classes.
Model: "sequential"
_________________________________________________________________
 Layer (type)                Output Shape              Param #
=================================================================
 conv2d (Conv2D)             (None, 478, 638, 16)      448
 max_pooling2d (MaxPooling2D  (None, 239, 319, 16)     0
 )
 dropout (Dropout)           (None, 239, 319, 16)      0
 conv2d_1 (Conv2D)           (None, 237, 317, 32)      4640
 max_pooling2d_1 (MaxPooling  (None, 118, 158, 32)     0
 2D)
 dropout_1 (Dropout)         (None, 118, 158, 32)      0
 conv2d_2 (Conv2D)           (None, 116, 156, 64)      18496
 max_pooling2d_2 (MaxPooling  (None, 58, 78, 64)       0
 2D)
 dropout_2 (Dropout)         (None, 58, 78, 64)        0
 conv2d_3 (Conv2D)           (None, 56, 76, 128)       73856
 max_pooling2d_3 (MaxPooling  (None, 28, 38, 128)      0
 2D)
 dropout_3 (Dropout)         (None, 28, 38, 128)       0
 global_average_pooling2d (G  (None, 128)              0
 lobalAveragePooling2D)
 dense (Dense)               (None, 4)                 516
=================================================================
Total params: 97,956
Trainable params: 97,956
Non-trainable params: 0
_________________________________________________________________
wandb: WARNING The save_model argument by default saves the model in the HDF5 format that cannot save custom objects like subclassed models and custom layers. This behavior will be deprecated in a future release in favor of the SavedModel format. Meanwhile, the HDF5 model is saved as W&B files and the SavedModel as W&B Artifacts.
Traceback (most recent call last):
  File "C:\Users\Anthony Popa\feces_thesis\2dCNN.py", line 77, in <module>
    model.fit(train_generator, validation_data=val_generator, epochs=wandb.config.epochs, batch_size=wandb.config.batch_size,
  File "C:\Users\Anthony Popa\anaconda3\lib\site-packages\wandb\integration\keras\keras.py", line 163, in new_v2
    return old_v2(*args, **kwargs)
  File "C:\Users\Anthony Popa\anaconda3\lib\site-packages\keras\utils\traceback_utils.py", line 67, in error_handler
    raise e.with_traceback(filtered_tb) from None
  File "C:\Users\Anthony Popa\anaconda3\lib\site-packages\keras\preprocessing\image.py", line 100, in __getitem__
    raise ValueError('Asked to retrieve element {idx}, '
ValueError: Asked to retrieve element 0, but the Sequence has length 0